[2022-03-21 02:29:12,546] {taskinstance.py:1032} INFO - Dependencies all met for <TaskInstance: data_ingestion_gcs_dag.download_stocks_list scheduled__2022-03-20T00:00:00+00:00 [queued]>
[2022-03-21 02:29:12,559] {taskinstance.py:1032} INFO - Dependencies all met for <TaskInstance: data_ingestion_gcs_dag.download_stocks_list scheduled__2022-03-20T00:00:00+00:00 [queued]>
[2022-03-21 02:29:12,560] {taskinstance.py:1238} INFO - 
--------------------------------------------------------------------------------
[2022-03-21 02:29:12,561] {taskinstance.py:1239} INFO - Starting attempt 3 of 4
[2022-03-21 02:29:12,562] {taskinstance.py:1240} INFO - 
--------------------------------------------------------------------------------
[2022-03-21 02:29:12,573] {taskinstance.py:1259} INFO - Executing <Task(PythonOperator): download_stocks_list> on 2022-03-20 00:00:00+00:00
[2022-03-21 02:29:12,579] {standard_task_runner.py:52} INFO - Started process 150 to run task
[2022-03-21 02:29:12,583] {standard_task_runner.py:76} INFO - Running: ['***', 'tasks', 'run', 'data_ingestion_gcs_dag', 'download_stocks_list', 'scheduled__2022-03-20T00:00:00+00:00', '--job-id', '6650', '--raw', '--subdir', 'DAGS_FOLDER/daily_stocks_dag.py', '--cfg-path', '/tmp/tmpxg3mrc1_', '--error-file', '/tmp/tmp73927qez']
[2022-03-21 02:29:12,585] {standard_task_runner.py:77} INFO - Job 6650: Subtask download_stocks_list
[2022-03-21 02:29:12,654] {logging_mixin.py:109} INFO - Running <TaskInstance: data_ingestion_gcs_dag.download_stocks_list scheduled__2022-03-20T00:00:00+00:00 [running]> on host 5df3b6bcd0b9
[2022-03-21 02:29:12,718] {taskinstance.py:1426} INFO - Exporting the following env vars:
AIRFLOW_CTX_DAG_OWNER=***
AIRFLOW_CTX_DAG_ID=data_ingestion_gcs_dag
AIRFLOW_CTX_TASK_ID=download_stocks_list
AIRFLOW_CTX_EXECUTION_DATE=2022-03-20T00:00:00+00:00
AIRFLOW_CTX_DAG_RUN_ID=scheduled__2022-03-20T00:00:00+00:00
[2022-03-21 02:29:12,973] {logging_mixin.py:109} INFO - 0 : AAIT,
[2022-03-21 02:29:12,993] {logging_mixin.py:109} WARNING - Exception in thread Thread-1:
Traceback (most recent call last):
  File "/usr/local/lib/python3.7/threading.py", line 926, in _bootstrap_inner
    self.run()
  File "/usr/local/lib/python3.7/threading.py", line 870, in run
    self._target(*self._args, **self._kwargs)
  File "/home/***/.local/lib/python3.7/site-packages/multitasking/__init__.py", line 104, in _run_via_pool
    return callee(*args, **kwargs)
  File "/home/***/.local/lib/python3.7/site-packages/yfinance/multi.py", line 190, in _download_one_threaded
    timeout)
  File "/home/***/.local/lib/python3.7/site-packages/yfinance/multi.py", line 207, in _download_one
    timeout=timeout)
  File "/home/***/.local/lib/python3.7/site-packages/yfinance/base.py", line 159, in history
    end = int(_time.mktime(_time.strptime(str(end), '%Y-%m-%d')))
  File "/usr/local/lib/python3.7/_strptime.py", line 571, in _strptime_time
    tt = _strptime(data_string, format)[0]
  File "/usr/local/lib/python3.7/_strptime.py", line 359, in _strptime
    (data_string, format))
ValueError: time data ' 2022-03-20' does not match format '%Y-%m-%d'
[2022-03-21 02:29:12,994] {logging_mixin.py:109} WARNING - 
