[2022-03-16 23:40:59,867] {taskinstance.py:1032} INFO - Dependencies all met for <TaskInstance: pbp_bucket_ingestion_dag.get_pbp_data scheduled__2013-01-27T04:00:00+00:00 [queued]>
[2022-03-16 23:40:59,885] {taskinstance.py:1032} INFO - Dependencies all met for <TaskInstance: pbp_bucket_ingestion_dag.get_pbp_data scheduled__2013-01-27T04:00:00+00:00 [queued]>
[2022-03-16 23:40:59,886] {taskinstance.py:1238} INFO - 
--------------------------------------------------------------------------------
[2022-03-16 23:40:59,887] {taskinstance.py:1239} INFO - Starting attempt 1 of 1
[2022-03-16 23:40:59,888] {taskinstance.py:1240} INFO - 
--------------------------------------------------------------------------------
[2022-03-16 23:40:59,945] {taskinstance.py:1259} INFO - Executing <Task(PythonOperator): get_pbp_data> on 2013-01-27 04:00:00+00:00
[2022-03-16 23:40:59,968] {standard_task_runner.py:76} INFO - Running: ['***', 'tasks', 'run', 'pbp_bucket_ingestion_dag', 'get_pbp_data', 'scheduled__2013-01-27T04:00:00+00:00', '--job-id', '4913', '--raw', '--subdir', 'DAGS_FOLDER/pbp_ingestion_dag.py', '--cfg-path', '/tmp/tmp1qed_j6g', '--error-file', '/tmp/tmp6d76qomx']
[2022-03-16 23:40:59,961] {standard_task_runner.py:52} INFO - Started process 902 to run task
[2022-03-16 23:40:59,970] {standard_task_runner.py:77} INFO - Job 4913: Subtask get_pbp_data
[2022-03-16 23:41:00,237] {logging_mixin.py:109} INFO - Running <TaskInstance: pbp_bucket_ingestion_dag.get_pbp_data scheduled__2013-01-27T04:00:00+00:00 [running]> on host 18c4eae34c61
[2022-03-16 23:41:00,331] {warnings.py:110} WARNING - /home/***/.local/lib/python3.7/site-packages/***/utils/context.py:152: AirflowContextDeprecationWarning: Accessing 'execution_date' from the template is deprecated and will be removed in a future version. Please use 'data_interval_start' or 'logical_date' instead.
  warnings.warn(_create_deprecation_warning(key, self._deprecation_replacements[key]))

[2022-03-16 23:41:00,373] {taskinstance.py:1426} INFO - Exporting the following env vars:
AIRFLOW_CTX_DAG_OWNER=***
AIRFLOW_CTX_DAG_ID=pbp_bucket_ingestion_dag
AIRFLOW_CTX_TASK_ID=get_pbp_data
AIRFLOW_CTX_EXECUTION_DATE=2013-01-27T04:00:00+00:00
AIRFLOW_CTX_DAG_RUN_ID=scheduled__2013-01-27T04:00:00+00:00
[2022-03-16 23:41:00,777] {taskinstance.py:1700} ERROR - Task failed with exception
Traceback (most recent call last):
  File "/home/airflow/.local/lib/python3.7/site-packages/airflow/models/taskinstance.py", line 1329, in _run_raw_task
    self._execute_task_with_callbacks(context)
  File "/home/airflow/.local/lib/python3.7/site-packages/airflow/models/taskinstance.py", line 1455, in _execute_task_with_callbacks
    result = self._execute_task(context, self.task)
  File "/home/airflow/.local/lib/python3.7/site-packages/airflow/models/taskinstance.py", line 1511, in _execute_task
    result = execute_callable(context=context)
  File "/home/airflow/.local/lib/python3.7/site-packages/airflow/operators/python.py", line 174, in execute
    return_value = self.execute_callable()
  File "/home/airflow/.local/lib/python3.7/site-packages/airflow/operators/python.py", line 185, in execute_callable
    return self.python_callable(*self.op_args, **self.op_kwargs)
  File "/opt/airflow/dags/pbp_ingestion_dag.py", line 63, in get_pbp_data
    for game in games['dates'][0]['games']:
IndexError: list index out of range
[2022-03-16 23:41:00,850] {taskinstance.py:1277} INFO - Marking task as FAILED. dag_id=pbp_bucket_ingestion_dag, task_id=get_pbp_data, execution_date=20130127T040000, start_date=20220316T234059, end_date=20220316T234100
[2022-03-16 23:41:00,899] {standard_task_runner.py:92} ERROR - Failed to execute job 4913 for task get_pbp_data
Traceback (most recent call last):
  File "/home/airflow/.local/lib/python3.7/site-packages/airflow/task/task_runner/standard_task_runner.py", line 85, in _start_by_fork
    args.func(args, dag=self.dag)
  File "/home/airflow/.local/lib/python3.7/site-packages/airflow/cli/cli_parser.py", line 48, in command
    return func(*args, **kwargs)
  File "/home/airflow/.local/lib/python3.7/site-packages/airflow/utils/cli.py", line 92, in wrapper
    return f(*args, **kwargs)
  File "/home/airflow/.local/lib/python3.7/site-packages/airflow/cli/commands/task_command.py", line 298, in task_run
    _run_task_by_selected_method(args, dag, ti)
  File "/home/airflow/.local/lib/python3.7/site-packages/airflow/cli/commands/task_command.py", line 107, in _run_task_by_selected_method
    _run_raw_task(args, ti)
  File "/home/airflow/.local/lib/python3.7/site-packages/airflow/cli/commands/task_command.py", line 184, in _run_raw_task
    error_file=args.error_file,
  File "/home/airflow/.local/lib/python3.7/site-packages/airflow/utils/session.py", line 70, in wrapper
    return func(*args, session=session, **kwargs)
  File "/home/airflow/.local/lib/python3.7/site-packages/airflow/models/taskinstance.py", line 1329, in _run_raw_task
    self._execute_task_with_callbacks(context)
  File "/home/airflow/.local/lib/python3.7/site-packages/airflow/models/taskinstance.py", line 1455, in _execute_task_with_callbacks
    result = self._execute_task(context, self.task)
  File "/home/airflow/.local/lib/python3.7/site-packages/airflow/models/taskinstance.py", line 1511, in _execute_task
    result = execute_callable(context=context)
  File "/home/airflow/.local/lib/python3.7/site-packages/airflow/operators/python.py", line 174, in execute
    return_value = self.execute_callable()
  File "/home/airflow/.local/lib/python3.7/site-packages/airflow/operators/python.py", line 185, in execute_callable
    return self.python_callable(*self.op_args, **self.op_kwargs)
  File "/opt/airflow/dags/pbp_ingestion_dag.py", line 63, in get_pbp_data
    for game in games['dates'][0]['games']:
IndexError: list index out of range
[2022-03-16 23:41:00,992] {local_task_job.py:154} INFO - Task exited with return code 1
[2022-03-16 23:41:01,097] {local_task_job.py:264} INFO - 0 downstream tasks scheduled from follow-on schedule check
