[2022-03-17 00:53:20,211] {taskinstance.py:1032} INFO - Dependencies all met for <TaskInstance: pbp_bucket_ingestion_dag.get_pbp_data scheduled__2014-03-06T04:00:00+00:00 [queued]>
[2022-03-17 00:53:20,266] {taskinstance.py:1032} INFO - Dependencies all met for <TaskInstance: pbp_bucket_ingestion_dag.get_pbp_data scheduled__2014-03-06T04:00:00+00:00 [queued]>
[2022-03-17 00:53:20,273] {taskinstance.py:1238} INFO - 
--------------------------------------------------------------------------------
[2022-03-17 00:53:20,282] {taskinstance.py:1239} INFO - Starting attempt 1 of 1
[2022-03-17 00:53:20,293] {taskinstance.py:1240} INFO - 
--------------------------------------------------------------------------------
[2022-03-17 00:53:20,359] {taskinstance.py:1259} INFO - Executing <Task(PythonOperator): get_pbp_data> on 2014-03-06 04:00:00+00:00
[2022-03-17 00:53:20,374] {standard_task_runner.py:52} INFO - Started process 300 to run task
[2022-03-17 00:53:20,405] {standard_task_runner.py:76} INFO - Running: ['***', 'tasks', 'run', 'pbp_bucket_ingestion_dag', 'get_pbp_data', 'scheduled__2014-03-06T04:00:00+00:00', '--job-id', '5322', '--raw', '--subdir', 'DAGS_FOLDER/pbp_ingestion_dag.py', '--cfg-path', '/tmp/tmpwt5ac57q', '--error-file', '/tmp/tmpg3mgbxxg']
[2022-03-17 00:53:20,413] {standard_task_runner.py:77} INFO - Job 5322: Subtask get_pbp_data
[2022-03-17 00:53:20,586] {logging_mixin.py:109} INFO - Running <TaskInstance: pbp_bucket_ingestion_dag.get_pbp_data scheduled__2014-03-06T04:00:00+00:00 [running]> on host 7372e643ccbb
[2022-03-17 00:53:20,762] {taskinstance.py:1426} INFO - Exporting the following env vars:
AIRFLOW_CTX_DAG_OWNER=***
AIRFLOW_CTX_DAG_ID=pbp_bucket_ingestion_dag
AIRFLOW_CTX_TASK_ID=get_pbp_data
AIRFLOW_CTX_EXECUTION_DATE=2014-03-06T04:00:00+00:00
AIRFLOW_CTX_DAG_RUN_ID=scheduled__2014-03-06T04:00:00+00:00
[2022-03-17 00:53:21,856] {taskinstance.py:1700} ERROR - Task failed with exception
Traceback (most recent call last):
  File "/home/airflow/.local/lib/python3.7/site-packages/airflow/models/taskinstance.py", line 1329, in _run_raw_task
    self._execute_task_with_callbacks(context)
  File "/home/airflow/.local/lib/python3.7/site-packages/airflow/models/taskinstance.py", line 1455, in _execute_task_with_callbacks
    result = self._execute_task(context, self.task)
  File "/home/airflow/.local/lib/python3.7/site-packages/airflow/models/taskinstance.py", line 1511, in _execute_task
    result = execute_callable(context=context)
  File "/home/airflow/.local/lib/python3.7/site-packages/airflow/operators/python.py", line 174, in execute
    return_value = self.execute_callable()
  File "/home/airflow/.local/lib/python3.7/site-packages/airflow/operators/python.py", line 185, in execute_callable
    return self.python_callable(*self.op_args, **self.op_kwargs)
  File "/opt/airflow/dags/pbp_ingestion_dag.py", line 53, in get_pbp_data
    upload_json_object(r, f'{GCS_PATH_TEMPLATE}/game_{game_id}.json')
  File "/opt/airflow/dags/pbp_ingestion_dag.py", line 19, in upload_json_object
    BUCKET = storage_client.get_bucket(BUCKET_NAME)
NameError: name 'storage_client' is not defined
[2022-03-17 00:53:21,950] {taskinstance.py:1277} INFO - Marking task as FAILED. dag_id=pbp_bucket_ingestion_dag, task_id=get_pbp_data, execution_date=20140306T040000, start_date=20220317T005320, end_date=20220317T005321
[2022-03-17 00:53:22,039] {standard_task_runner.py:92} ERROR - Failed to execute job 5322 for task get_pbp_data
Traceback (most recent call last):
  File "/home/airflow/.local/lib/python3.7/site-packages/airflow/task/task_runner/standard_task_runner.py", line 85, in _start_by_fork
    args.func(args, dag=self.dag)
  File "/home/airflow/.local/lib/python3.7/site-packages/airflow/cli/cli_parser.py", line 48, in command
    return func(*args, **kwargs)
  File "/home/airflow/.local/lib/python3.7/site-packages/airflow/utils/cli.py", line 92, in wrapper
    return f(*args, **kwargs)
  File "/home/airflow/.local/lib/python3.7/site-packages/airflow/cli/commands/task_command.py", line 298, in task_run
    _run_task_by_selected_method(args, dag, ti)
  File "/home/airflow/.local/lib/python3.7/site-packages/airflow/cli/commands/task_command.py", line 107, in _run_task_by_selected_method
    _run_raw_task(args, ti)
  File "/home/airflow/.local/lib/python3.7/site-packages/airflow/cli/commands/task_command.py", line 184, in _run_raw_task
    error_file=args.error_file,
  File "/home/airflow/.local/lib/python3.7/site-packages/airflow/utils/session.py", line 70, in wrapper
    return func(*args, session=session, **kwargs)
  File "/home/airflow/.local/lib/python3.7/site-packages/airflow/models/taskinstance.py", line 1329, in _run_raw_task
    self._execute_task_with_callbacks(context)
  File "/home/airflow/.local/lib/python3.7/site-packages/airflow/models/taskinstance.py", line 1455, in _execute_task_with_callbacks
    result = self._execute_task(context, self.task)
  File "/home/airflow/.local/lib/python3.7/site-packages/airflow/models/taskinstance.py", line 1511, in _execute_task
    result = execute_callable(context=context)
  File "/home/airflow/.local/lib/python3.7/site-packages/airflow/operators/python.py", line 174, in execute
    return_value = self.execute_callable()
  File "/home/airflow/.local/lib/python3.7/site-packages/airflow/operators/python.py", line 185, in execute_callable
    return self.python_callable(*self.op_args, **self.op_kwargs)
  File "/opt/airflow/dags/pbp_ingestion_dag.py", line 53, in get_pbp_data
    upload_json_object(r, f'{GCS_PATH_TEMPLATE}/game_{game_id}.json')
  File "/opt/airflow/dags/pbp_ingestion_dag.py", line 19, in upload_json_object
    BUCKET = storage_client.get_bucket(BUCKET_NAME)
NameError: name 'storage_client' is not defined
[2022-03-17 00:53:22,134] {local_task_job.py:154} INFO - Task exited with return code 1
[2022-03-17 00:53:22,344] {local_task_job.py:264} INFO - 0 downstream tasks scheduled from follow-on schedule check
