[2022-03-18 15:24:00,875] {taskinstance.py:1032} INFO - Dependencies all met for <TaskInstance: pbp_bucket_ingestion_dag.get_pbp_data scheduled__2011-06-15T04:00:00+00:00 [queued]>
[2022-03-18 15:24:00,913] {taskinstance.py:1032} INFO - Dependencies all met for <TaskInstance: pbp_bucket_ingestion_dag.get_pbp_data scheduled__2011-06-15T04:00:00+00:00 [queued]>
[2022-03-18 15:24:00,915] {taskinstance.py:1238} INFO - 
--------------------------------------------------------------------------------
[2022-03-18 15:24:00,917] {taskinstance.py:1239} INFO - Starting attempt 2 of 3
[2022-03-18 15:24:00,920] {taskinstance.py:1240} INFO - 
--------------------------------------------------------------------------------
[2022-03-18 15:24:00,976] {taskinstance.py:1259} INFO - Executing <Task(PythonOperator): get_pbp_data> on 2011-06-15 04:00:00+00:00
[2022-03-18 15:24:00,989] {standard_task_runner.py:52} INFO - Started process 619 to run task
[2022-03-18 15:24:01,026] {standard_task_runner.py:76} INFO - Running: ['***', 'tasks', 'run', 'pbp_bucket_ingestion_dag', 'get_pbp_data', 'scheduled__2011-06-15T04:00:00+00:00', '--job-id', '6504', '--raw', '--subdir', 'DAGS_FOLDER/pbp_ingestion_dag.py', '--cfg-path', '/tmp/tmpvanq3gtq', '--error-file', '/tmp/tmp4tioh7qn']
[2022-03-18 15:24:01,034] {standard_task_runner.py:77} INFO - Job 6504: Subtask get_pbp_data
[2022-03-18 15:24:01,183] {logging_mixin.py:109} INFO - Running <TaskInstance: pbp_bucket_ingestion_dag.get_pbp_data scheduled__2011-06-15T04:00:00+00:00 [running]> on host 9a1698cd207d
[2022-03-18 15:24:01,397] {taskinstance.py:1426} INFO - Exporting the following env vars:
AIRFLOW_CTX_DAG_OWNER=***
AIRFLOW_CTX_DAG_ID=pbp_bucket_ingestion_dag
AIRFLOW_CTX_TASK_ID=get_pbp_data
AIRFLOW_CTX_EXECUTION_DATE=2011-06-15T04:00:00+00:00
AIRFLOW_CTX_DAG_RUN_ID=scheduled__2011-06-15T04:00:00+00:00
[2022-03-18 15:24:19,365] {taskinstance.py:1700} ERROR - Task failed with exception
Traceback (most recent call last):
  File "/home/airflow/.local/lib/python3.7/site-packages/airflow/models/taskinstance.py", line 1329, in _run_raw_task
    self._execute_task_with_callbacks(context)
  File "/home/airflow/.local/lib/python3.7/site-packages/airflow/models/taskinstance.py", line 1455, in _execute_task_with_callbacks
    result = self._execute_task(context, self.task)
  File "/home/airflow/.local/lib/python3.7/site-packages/airflow/models/taskinstance.py", line 1511, in _execute_task
    result = execute_callable(context=context)
  File "/home/airflow/.local/lib/python3.7/site-packages/airflow/operators/python.py", line 174, in execute
    return_value = self.execute_callable()
  File "/home/airflow/.local/lib/python3.7/site-packages/airflow/operators/python.py", line 185, in execute_callable
    return self.python_callable(*self.op_args, **self.op_kwargs)
  File "/opt/airflow/dags/pbp_ingestion_dag.py", line 94, in get_pbp_data
    games = r.json()
  File "/home/airflow/.local/lib/python3.7/site-packages/requests/models.py", line 910, in json
    return complexjson.loads(self.text, **kwargs)
  File "/usr/local/lib/python3.7/json/__init__.py", line 348, in loads
    return _default_decoder.decode(s)
  File "/usr/local/lib/python3.7/json/decoder.py", line 337, in decode
    obj, end = self.raw_decode(s, idx=_w(s, 0).end())
  File "/usr/local/lib/python3.7/json/decoder.py", line 355, in raw_decode
    raise JSONDecodeError("Expecting value", s, err.value) from None
json.decoder.JSONDecodeError: Expecting value: line 1 column 1 (char 0)
[2022-03-18 15:24:19,400] {taskinstance.py:1277} INFO - Marking task as UP_FOR_RETRY. dag_id=pbp_bucket_ingestion_dag, task_id=get_pbp_data, execution_date=20110615T040000, start_date=20220318T152400, end_date=20220318T152419
[2022-03-18 15:24:19,627] {standard_task_runner.py:92} ERROR - Failed to execute job 6504 for task get_pbp_data
Traceback (most recent call last):
  File "/home/airflow/.local/lib/python3.7/site-packages/airflow/task/task_runner/standard_task_runner.py", line 85, in _start_by_fork
    args.func(args, dag=self.dag)
  File "/home/airflow/.local/lib/python3.7/site-packages/airflow/cli/cli_parser.py", line 48, in command
    return func(*args, **kwargs)
  File "/home/airflow/.local/lib/python3.7/site-packages/airflow/utils/cli.py", line 92, in wrapper
    return f(*args, **kwargs)
  File "/home/airflow/.local/lib/python3.7/site-packages/airflow/cli/commands/task_command.py", line 298, in task_run
    _run_task_by_selected_method(args, dag, ti)
  File "/home/airflow/.local/lib/python3.7/site-packages/airflow/cli/commands/task_command.py", line 107, in _run_task_by_selected_method
    _run_raw_task(args, ti)
  File "/home/airflow/.local/lib/python3.7/site-packages/airflow/cli/commands/task_command.py", line 184, in _run_raw_task
    error_file=args.error_file,
  File "/home/airflow/.local/lib/python3.7/site-packages/airflow/utils/session.py", line 70, in wrapper
    return func(*args, session=session, **kwargs)
  File "/home/airflow/.local/lib/python3.7/site-packages/airflow/models/taskinstance.py", line 1329, in _run_raw_task
    self._execute_task_with_callbacks(context)
  File "/home/airflow/.local/lib/python3.7/site-packages/airflow/models/taskinstance.py", line 1455, in _execute_task_with_callbacks
    result = self._execute_task(context, self.task)
  File "/home/airflow/.local/lib/python3.7/site-packages/airflow/models/taskinstance.py", line 1511, in _execute_task
    result = execute_callable(context=context)
  File "/home/airflow/.local/lib/python3.7/site-packages/airflow/operators/python.py", line 174, in execute
    return_value = self.execute_callable()
  File "/home/airflow/.local/lib/python3.7/site-packages/airflow/operators/python.py", line 185, in execute_callable
    return self.python_callable(*self.op_args, **self.op_kwargs)
  File "/opt/airflow/dags/pbp_ingestion_dag.py", line 94, in get_pbp_data
    games = r.json()
  File "/home/airflow/.local/lib/python3.7/site-packages/requests/models.py", line 910, in json
    return complexjson.loads(self.text, **kwargs)
  File "/usr/local/lib/python3.7/json/__init__.py", line 348, in loads
    return _default_decoder.decode(s)
  File "/usr/local/lib/python3.7/json/decoder.py", line 337, in decode
    obj, end = self.raw_decode(s, idx=_w(s, 0).end())
  File "/usr/local/lib/python3.7/json/decoder.py", line 355, in raw_decode
    raise JSONDecodeError("Expecting value", s, err.value) from None
json.decoder.JSONDecodeError: Expecting value: line 1 column 1 (char 0)
[2022-03-18 15:24:19,672] {local_task_job.py:154} INFO - Task exited with return code 1
[2022-03-18 15:24:19,775] {local_task_job.py:264} INFO - 0 downstream tasks scheduled from follow-on schedule check
