[2022-03-16 23:21:50,600] {taskinstance.py:1032} INFO - Dependencies all met for <TaskInstance: pbp_bucket_ingestion_dag.get_pbp_data scheduled__2011-09-03T04:00:00+00:00 [queued]>
[2022-03-16 23:21:50,653] {taskinstance.py:1032} INFO - Dependencies all met for <TaskInstance: pbp_bucket_ingestion_dag.get_pbp_data scheduled__2011-09-03T04:00:00+00:00 [queued]>
[2022-03-16 23:21:50,657] {taskinstance.py:1238} INFO - 
--------------------------------------------------------------------------------
[2022-03-16 23:21:50,658] {taskinstance.py:1239} INFO - Starting attempt 1 of 1
[2022-03-16 23:21:50,663] {taskinstance.py:1240} INFO - 
--------------------------------------------------------------------------------
[2022-03-16 23:21:50,723] {taskinstance.py:1259} INFO - Executing <Task(PythonOperator): get_pbp_data> on 2011-09-03 04:00:00+00:00
[2022-03-16 23:21:50,739] {standard_task_runner.py:52} INFO - Started process 190 to run task
[2022-03-16 23:21:50,777] {standard_task_runner.py:76} INFO - Running: ['***', 'tasks', 'run', 'pbp_bucket_ingestion_dag', 'get_pbp_data', 'scheduled__2011-09-03T04:00:00+00:00', '--job-id', '4376', '--raw', '--subdir', 'DAGS_FOLDER/pbp_ingestion_dag.py', '--cfg-path', '/tmp/tmp8nb89bg_', '--error-file', '/tmp/tmpjq7l7p1a']
[2022-03-16 23:21:50,786] {standard_task_runner.py:77} INFO - Job 4376: Subtask get_pbp_data
[2022-03-16 23:21:50,919] {logging_mixin.py:109} INFO - Running <TaskInstance: pbp_bucket_ingestion_dag.get_pbp_data scheduled__2011-09-03T04:00:00+00:00 [running]> on host 1f84391c0e52
[2022-03-16 23:21:50,997] {warnings.py:110} WARNING - /home/***/.local/lib/python3.7/site-packages/***/utils/context.py:152: AirflowContextDeprecationWarning: Accessing 'execution_date' from the template is deprecated and will be removed in a future version. Please use 'data_interval_start' or 'logical_date' instead.
  warnings.warn(_create_deprecation_warning(key, self._deprecation_replacements[key]))

[2022-03-16 23:21:51,121] {taskinstance.py:1426} INFO - Exporting the following env vars:
AIRFLOW_CTX_DAG_OWNER=***
AIRFLOW_CTX_DAG_ID=pbp_bucket_ingestion_dag
AIRFLOW_CTX_TASK_ID=get_pbp_data
AIRFLOW_CTX_EXECUTION_DATE=2011-09-03T04:00:00+00:00
AIRFLOW_CTX_DAG_RUN_ID=scheduled__2011-09-03T04:00:00+00:00
[2022-03-16 23:21:51,460] {taskinstance.py:1700} ERROR - Task failed with exception
Traceback (most recent call last):
  File "/home/airflow/.local/lib/python3.7/site-packages/airflow/models/taskinstance.py", line 1329, in _run_raw_task
    self._execute_task_with_callbacks(context)
  File "/home/airflow/.local/lib/python3.7/site-packages/airflow/models/taskinstance.py", line 1455, in _execute_task_with_callbacks
    result = self._execute_task(context, self.task)
  File "/home/airflow/.local/lib/python3.7/site-packages/airflow/models/taskinstance.py", line 1511, in _execute_task
    result = execute_callable(context=context)
  File "/home/airflow/.local/lib/python3.7/site-packages/airflow/operators/python.py", line 174, in execute
    return_value = self.execute_callable()
  File "/home/airflow/.local/lib/python3.7/site-packages/airflow/operators/python.py", line 185, in execute_callable
    return self.python_callable(*self.op_args, **self.op_kwargs)
  File "/opt/airflow/dags/pbp_ingestion_dag.py", line 63, in get_pbp_data
    for game in games['dates'][0]['games']:
KeyError: 'dates'
[2022-03-16 23:21:51,514] {taskinstance.py:1277} INFO - Marking task as FAILED. dag_id=pbp_bucket_ingestion_dag, task_id=get_pbp_data, execution_date=20110903T040000, start_date=20220316T232150, end_date=20220316T232151
[2022-03-16 23:21:51,579] {standard_task_runner.py:92} ERROR - Failed to execute job 4376 for task get_pbp_data
Traceback (most recent call last):
  File "/home/airflow/.local/lib/python3.7/site-packages/airflow/task/task_runner/standard_task_runner.py", line 85, in _start_by_fork
    args.func(args, dag=self.dag)
  File "/home/airflow/.local/lib/python3.7/site-packages/airflow/cli/cli_parser.py", line 48, in command
    return func(*args, **kwargs)
  File "/home/airflow/.local/lib/python3.7/site-packages/airflow/utils/cli.py", line 92, in wrapper
    return f(*args, **kwargs)
  File "/home/airflow/.local/lib/python3.7/site-packages/airflow/cli/commands/task_command.py", line 298, in task_run
    _run_task_by_selected_method(args, dag, ti)
  File "/home/airflow/.local/lib/python3.7/site-packages/airflow/cli/commands/task_command.py", line 107, in _run_task_by_selected_method
    _run_raw_task(args, ti)
  File "/home/airflow/.local/lib/python3.7/site-packages/airflow/cli/commands/task_command.py", line 184, in _run_raw_task
    error_file=args.error_file,
  File "/home/airflow/.local/lib/python3.7/site-packages/airflow/utils/session.py", line 70, in wrapper
    return func(*args, session=session, **kwargs)
  File "/home/airflow/.local/lib/python3.7/site-packages/airflow/models/taskinstance.py", line 1329, in _run_raw_task
    self._execute_task_with_callbacks(context)
  File "/home/airflow/.local/lib/python3.7/site-packages/airflow/models/taskinstance.py", line 1455, in _execute_task_with_callbacks
    result = self._execute_task(context, self.task)
  File "/home/airflow/.local/lib/python3.7/site-packages/airflow/models/taskinstance.py", line 1511, in _execute_task
    result = execute_callable(context=context)
  File "/home/airflow/.local/lib/python3.7/site-packages/airflow/operators/python.py", line 174, in execute
    return_value = self.execute_callable()
  File "/home/airflow/.local/lib/python3.7/site-packages/airflow/operators/python.py", line 185, in execute_callable
    return self.python_callable(*self.op_args, **self.op_kwargs)
  File "/opt/airflow/dags/pbp_ingestion_dag.py", line 63, in get_pbp_data
    for game in games['dates'][0]['games']:
KeyError: 'dates'
[2022-03-16 23:21:51,672] {local_task_job.py:154} INFO - Task exited with return code 1
[2022-03-16 23:21:51,811] {local_task_job.py:264} INFO - 0 downstream tasks scheduled from follow-on schedule check
